Workbook

Sheet peakflow_q1_2025_dirty
A1: DealID | B1: Date | C1: CustomerName | D1: CategoryName | E1: SalesRep | F1: Manager | G1: Region | H1: Units | I1: UnitPrice | J1: Revenue
A2: D-1088 | B2: 45658 | C2: Helix Systems | D2: Starter Plan | E2: Nina Petrov | F2: Lukas Becker | G2: North America | H2: 2 | I2: 44.27 | J2: 88.54
A3: D-1108 | B3: 45658 | C3: Meridian Group | D3: Pro Plan | E3: Tom Wilson | F3: Lukas Becker | G3: North America | H3: 10 | I3: 224.49 | J3: 125889
A4: D-1230 | B4: 45658 | C4: Fusion Group | D4: Pro Plan | E4: Marcus Johnson | F4: Sarah Chen | G4: LATAM | H4: 2 | I4: 248.58 | J4: $497.16
A5: D-1035 | B5: 45659 | C5: Nova Inc | D5: Add-on: Support | E5: Elena Rossi | F5: Lukas Becker | G5: EMEA | H5: 1 | I5: 112.19 | J5: 112.19
A6: D-1152 | B6: 45659 | C6: Catalyst Inc | D6: Starter Plan | E6: Elena Rossi | F6: Lukas Becker | G6: North America | H6: 1 | I6: 73.94 | J6: 73.94
A7: D-1202 | B7: 45659 | C7: Nimbus Co | D7: Business Plan | E7: James Park | F7: Owen Walsh | G7: North America | H7: 5 | I7: 369.19 | J7: 1845.95
A8: D-1249 | B8: 45659 | C8: Summit Group | D8: Enterprise Plan | E8: Elena Rossi | F8: Lukas Becker | G8: North America | H8: 1 | I8: 1198.59 | J8: 1198.59
A9: D-1054 | B9: 45661 | C9: Northwind Co | D9: Enterprise Plan | E9: David Kim | F9: Sarah Chen | G9: EMEA | H9: 2 | I9: 1182.78 | J9: 2365.56
A10: D-1102 | B10: 45661 | C10: Lumen Labs | D10: Starter Plan | E10: Carlos Mendez | F10: Maya Rodriguez | G10: EMEA | H10: 1 | I10: 68.06 | J10: 68.06
A11: D-1115 | B11: 45661 | C11: Kestrel Co | D11: Add-on: Support | E11: Tom Wilson | F11: Lukas Becker | G11: APAC | H11: 2 | I11: 118.97 | J11: 237.94
A12: D-1138 | B12: 45661 | C12: Nova Inc | D12: Starter Plan | E12: Marcus Johnson | F12: Sarah Chen | G12: LATAM | H12: 5 | I12: 53.28 | J12: 266.4
A13: D-1231 | B13: 45661 | C13: Borealis Co | D13: Enterprise Plan | E13: Marcus Johnson | F13: Sarah Chen | G13: EMEA | H13: 1 | I13: 992.76 | J13: 992.76
A14: D-1008 | B14: 45662 | C14: Phoenix Co | D14: Pro Plan | E14: Tom Wilson | F14: Lukas Becker | G14: latam | H14: 20 | I14: 249.04 | J14: 1125162
A15: D-1071 | B15: 45662 | C15: Apex Group | D15: Business Plan | E15: David Kim | F15: Sarah Chen | G15: APAC | H15: 1 | I15: 386.52 | J15: 386.52
A16: D-1105 | B16: 45662 | C16: Kestrel Co | D16: Pro Plan | E16: Elena Rossi | F16: Lukas Becker | G16: North America | H16: 1 | I16: 226.12 | J16: $226.12
A17: D-1110 | B17: 45662 | C17: Rivet Co | D17: Starter Plan | E17: James Park | F17: Owen Walsh | G17: latam | H17: 1 | I17: 73.28 | J17: 73.28
A18: D-1112 | B18: 45662 | C18: Borealis Co | D18: Starter Plan | E18: Hannah Lee | F18: Owen Walsh | G18: EMEA | H18: 5 | I18: 45.99 | J18: $229.95
A19: D-1132 | B19: 45662 | C19: Quanta Labs | D19: Starter Plan | E19: Hannah Lee | F19: Owen Walsh | G19: APAC | H19: 50 | I19: 70.68 | J19: $3,534.00
A20: D-1150 | B20: 45662 | C20: Nimbus Co | D20: Pro Plan | E20: James Park | F20: Owen Walsh | G20: EMEA | H20: 20 | I20: 192.21 | J20: 710064
A21: D-1194 | B21: 45662 | C21: Onyx Group | D21: Pro Plan | E21: Sophie Laurent | F21: Maya Rodriguez | G21: North America | H21: 2 | I21: 193.5 | J21: $387.00
A22: D-1091 | B22: 45663 | C22: Fusion Group | D22: Starter Plan | E22: Marcus Johnson | F22: Sarah Chen | G22: APAC | H22: 1 | I22: 53.39 | J22: $53.39
A23: D-1092 | B23: 45663 | C23: Summit Group | D23: Pro Plan | E23: Carlos Mendez | F23: Maya Rodriguez | G23: APAC | H23: 1 | I23: 202.22 | J23: 202.22
A24: D-1211 | B24: 45663 | C24: Apex Group | D24: Add-on: Analytics | E24: James Park | F24: Owen Walsh | G24: LATAM | H24: 5 | I24: 69.69 | J24: $348.45
A25: D-1063 | B25: 45664 | C25: Granite Co | D25: Add-on: Support | E25: Marcus Johnson | F25: Sarah Chen | G25: North America | H25: 1 | I25: 93.27 | J25: 93.27
A26: D-1206 | B26: 45664 | C26: Stellar Co | D26: Add-on: Analytics | E26: Elena Rossi | F26: Lukas Becker | G26: APAC | H26: 5 | I26: 74.69 | J26: 373.45
A27: D-1123 | B27: 45665 | C27: Nimbus Co | D27: Add-on: Support | E27: Tom Wilson | F27: Lukas Becker | G27: latam | H27: 1 | I27: 92.92 | J27: 92.92
A28: D-1121 | B28: 45666 | C28: Nova Inc | D28: Enterprise Plan | E28: Priya Patel | F28: Maya Rodriguez | G28: APAC | H28: 1 | I28: 1388.69 | J28: $1,388.69
A29: D-1029 | B29: 45667 | C29: Cascade Group | D29: Starter Plan | E29: Sophie Laurent | F29: Maya Rodriguez | G29: APAC | H29: 50 | I29: 72.26 | J29: 3613.0
A30: D-1141 | B30: 45667 | C30: Nova Inc | D30: Enterprise Plan | E30: Elena Rossi | F30: Lukas Becker | G30: APAC | H30: 1 | I30: 1234.13 | J30: $1234.13
A31: D-1155 | B31: 45667 | C31: Juniper Group | D31: Pro Plan | E31: Nina Petrov | F31: Lukas Becker | G31: North America | H31: 1 | I31: 219.47 | J31: 219.47
A32: D-1209 | B32: 45667 | C32: Lattice Co | D32: Pro Plan | E32: Elena Rossi | F32: Lukas Becker | G32: North America | H32: 1 | I32: 276.18 | J32: $276.18
... A42: D-1220 | B42: 45669 | C42: Echo Labs | D42: Add-on: Analytics | E42: Marcus Johnson | F42: Sarah Chen | G42: North America | H42: 1 | I42: 92.43 | J42: 92.43
A43: D-1058 | B43: 45670 | C43: Nimbus Co | D43: Business Plan | E43: Marcus Johnson | F43: Sarah Chen | G43: APAC | H43: 5 | I43: 422.7 | J43: 77919
A44: D-1229 | B44: 45670 | C44: Arcadia Inc | D44: Business Plan | E44: David Kim | F44: Sarah Chen | G44: EMEA | H44: 2 | I44: 409.02 | J44: 818.04
A45: D-1245 | B45: 45670 | C45: Quill Labs | D45: Pro Plan | E45: Priya Patel | F45: Maya Rodriguez | G45: North America | H45: 5 | I45: 177.21 | J45: $886.05
A46: D-1075 | B46: 45671 | C46: Beacon Labs | D46: Pro Plan | E46: Carlos Mendez | F46: Maya Rodriguez | G46: APAC | H46: 5 | I46: 230.19 | J46: $1,150.95
A47: D-1079 | B47: 45671 | C47: Onyx Group | D47: Starter Plan | E47: Nina Petrov | F47: Lukas Becker | G47: North America | H47: 1 | I47: 66.71 | J47: 66.71
A48: D-1169 | B48: 45671 | C48: Quartz Co | D48: Business Plan | E48: David Kim | F48: Sarah Chen | G48: EMEA | H48: 1 | I48: 426.07 | J48: $426.07
A49: D-1234 | B49: 45671 | C49: Pacific Co | D49: Pro Plan | E49: Priya Patel | F49: Maya Rodriguez | G49: North America | H49: 2 | I49: 233.74 | J49: $467.48
...

Sheet Geschäfte
A1: PeakFlow Q1 2025 - bereinigte Geschäftsdaten
M2: Hilfstabelle für Streudiagramm
A3: DealID | B3: Date | C3: CustomerName | D3: CategoryName | E3: SalesRep | F3: Manager | G3: =TRIM(CLEAN(PROPER(peakflow_q1_2025_dirty!G1))) -> Region | H3: Units | I3: UnitPrice | J3: Revenue | K3: Monat | M3: Add-On: Analytics Units | N3: Add-On: Analytics Price | O3: Add on: Support Unit | P3: Add on: Support Unit Price | Q3: Business Plan Unit | R3: Business Plan Unit Price | S3: Enterprise Plan Unit | T3: Enterprise Unit Price | U3: Pro Plan Unit | V3: Pro Plan Unit Price | W3: Starter Plan Unit | X3: Starter Plan Unit Price
A4: =TRIM(CLEAN(PROPER(peakflow_q1_2025_dirty!A2))) -> D-1088 | B4: =DATEVALUE(TRIM(CLEAN(peakflow_q1_2025_dirty!B2))) -> 45658 | C4: =TRIM(CLEAN(PROPER(peakflow_q1_2025_dirty!C2))) -> Helix Systems | D4: =TRIM(CLEAN(PROPER(peakflow_q1_2025_dirty!D2))) -> Starter Plan | E4: =TRIM(CLEAN(PROPER(peakflow_q1_2025_dirty!E2))) -> Nina Petrov | F4: =TRIM(CLEAN(PROPER(peakflow_q1_2025_dirty!F2))) -> Lukas Becker | G4: =TRIM(CLEAN(PROPER(peakflow_q1_2025_dirty!G2))) -> North America | H4: =VALUE(TRIM((CLEAN(peakflow_q1_2025_dirty!H2)))) -> 2 | I4: =VALUE(SUBSTITUTE(peakflow_q1_2025_dirty!I2,".","," )) -> 44.27 | J4: =H4*I4 -> 88.54 | K4: =TEXT(B4,"MMMM") -> Januar | M4: =IF($D4="Add-On: Analytics",$H4,NA()) -> #N/A | N4: =IF($D4="Add-On: Analytics",$I4,NA()) -> #N/A | O4: =IF($D4="Add-On: Support",$H4,NA()) -> #N/A | P4: =IF($D4="Add-On: Support",$I4,NA()) -> #N/A | Q4: =IF($D4="Business Plan",$H4,NA()) -> #N/A | R4: =IF($D4="Business Plan",$I4,NA()) -> #N/A | S4: =IF($D4="Enterprise Plan",$H4,NA()) -> #N/A | T4: =IF($D4="Enterprise Plan",$I4,NA()) -> #N/A | U4: =IF($D4="Pro Plan",$H4,NA()) -> #N/A | V4: =IF($D4="Pro Plan",$I4,NA()) -> #N/A | W4: =IF($D4="Starter Plan",$H4,NA()) -> 2 | X4: =IF($D4="Starter Plan",$I4,NA()) -> 44.27
A5: =TRIM(CLEAN(PROPER(peakflow_q1_2025_dirty!A3))) -> D-1108 | B5: =DATEVALUE(TRIM(CLEAN(peakflow_q1_2025_dirty!B3))) -> 45658 | C5: =TRIM(CLEAN(PROPER(peakflow_q1_2025_dirty!C3))) -> Meridian Group | D5: =TRIM(CLEAN(PROPER(peakflow_q1_2025_dirty!D3))) -> Pro Plan | E5: =TRIM(CLEAN(PROPER(peakflow_q1_2025_dirty!E3))) -> Tom Wilson | F5: =TRIM(CLEAN(PROPER(peakflow_q1_2025_dirty!F3))) -> Lukas Becker | G5: =TRIM(CLEAN(PROPER(peakflow_q1_2025_dirty!G3))) -> North America | H5: =VALUE(TRIM((CLEAN(peakflow_q1_2025_dirty!H3)))) -> 10 | I5: =VALUE(SUBSTITUTE(peakflow_q1_2025_dirty!I3,".","," )) -> 224.49 | J5: =H5*I5 -> 2244.9 | K5: =TEXT(B5,"MMMM") -> Januar | M5: =IF($D5="Add-On: Analytics",$H5,NA()) -> #N/A | N5: =IF($D5="Add-On: Analytics",$I5,NA()) -> #N/A | O5: =IF($D5="Add-On: Support",$H5,NA()) -> #N/A | P5: =IF($D5="Add-On: Support",$I5,NA()) -> #N/A | Q5: =IF($D5="Business Plan",$H5,NA()) -> #N/A | R5: =IF($D5="Business Plan",$I5,NA()) -> #N/A | S5: =IF($D5="Enterprise Plan",$H5,NA()) -> #N/A | T5: =IF($D5="Enterprise Plan",$I5,NA()) -> #N/A | U5: =IF($D5="Pro Plan",$H5,NA()) -> 10 | V5: =IF($D5="Pro Plan",$I5,NA()) -> 224.49 | W5: =IF($D5="Starter Plan",$H5,NA()) -> #N/A | X5: =IF($D5="Starter Plan",$I5,NA()) -> #N/A
A6: =TRIM(CLEAN(PROPER(peakflow_q1_2025_dirty!A4))) -> D-1230 | B6: =DATEVALUE(TRIM(CLEAN(peakflow_q1_2025_dirty!B4))) -> 45658 | C6: =TRIM(CLEAN(PROPER(peakflow_q1_2025_dirty!C4))) -> Fusion Group | D6: =TRIM(CLEAN(PROPER(peakflow_q1_2025_dirty!D4))) -> Pro Plan | E6: =TRIM(CLEAN(PROPER(peakflow_q1_2025_dirty!E4))) -> Marcus Johnson | F6: =TRIM(CLEAN(PROPER(peakflow_q1_2025_dirty!F4))) -> Sarah Chen | G6: =TRIM(CLEAN(UPPER(peakflow_q1_2025_dirty!G4))) -> LATAM | H6: =VALUE(TRIM((CLEAN(peakflow_q1_2025_dirty!H4)))) -> 2 | I6: =VALUE(SUBSTITUTE(peakflow_q1_2025_dirty!I4,".","," )) -> 248.58 | J6: =H6*I6 -> 497.16 | K6: =TEXT(B6,"MMMM") -> Januar | M6: =IF($D6="Add-On: Analytics",$H6,NA()) -> #N/A | N6: =IF($D6="Add-On: Analytics",$I6,NA()) -> #N/A | O6: =IF($D6="Add-On: Support",$H6,NA()) -> #N/A | P6: =IF($D6="Add-On: Support",$I6,NA()) -> #N/A | Q6: =IF($D6="Business Plan",$H6,NA()) -> #N/A | R6: =IF($D6="Business Plan",$I6,NA()) -> #N/A | S6: =IF($D6="Enterprise Plan",$H6,NA()) -> #N/A | T6: =IF($D6="Enterprise Plan",$I6,NA()) -> #N/A | U6: =IF($D6="Pro Plan",$H6,NA()) -> 2 | V6: =IF($D6="Pro Plan",$I6,NA()) -> 248.58 | W6: =IF($D6="Starter Plan",$H6,NA()) -> #N/A | X6: =IF($D6="Starter Plan",$I6,NA()) -> #N/A
A7: =TRIM(CLEAN(PROPER(peakflow_q1_2025_dirty!A5))) -> D-1035 | B7: =DATEVALUE(TRIM(CLEAN(peakflow_q1_2025_dirty!B5))) -> 45659 | C7: =TRIM(CLEAN(PROPER(peakflow_q1_2025_dirty!C5))) -> Nova Inc | D7: =TRIM(CLEAN(PROPER(peakflow_q1_2025_dirty!D5))) -> Add-On: Support | E7: =TRIM(CLEAN(PROPER(peakflow_q1_2025_dirty!E5))) -> Elena Rossi | F7: =TRIM(CLEAN(PROPER(peakflow_q1_2025_dirty!F5))) -> Lukas Becker | G7: =TRIM(CLEAN(UPPER(peakflow_q1_2025_dirty!G5))) -> EMEA | H7: =VALUE(TRIM((CLEAN(peakflow_q1_2025_dirty!H5)))) -> 1 | I7: =VALUE(SUBSTITUTE(peakflow_q1_2025_dirty!I5,".","," )) -> 112.19 | J7: =H7*I7 -> 112.19 | K7: =TEXT(B7,"MMMM") -> Januar | M7: =IF($D7="Add-On: Analytics",$H7,NA()) -> #N/A | N7: =IF($D7="Add-On: Analytics",$I7,NA()) -> #N/A | O7: =IF($D7="Add-On: Support",$H7,NA()) -> 1 | P7: =IF($D7="Add-On: Support",$I7,NA()) -> 112.19 | Q7: =IF($D7="Business Plan",$H7,NA()) -> #N/A | R7: =IF($D7="Business Plan",$I7,NA()) -> #N/A | S7: =IF($D7="Enterprise Plan",$H7,NA()) -> #N/A | T7: =IF($D7="Enterprise Plan",$I7,NA()) -> #N/A | U7: =IF($D7="Pro Plan",$H7,NA()) -> #N/A | V7: =IF($D7="Pro Plan",$I7,NA()) -> #N/A | W7: =IF($D7="Starter Plan",$H7,NA()) -> #N/A | X7: =IF($D7="Starter Plan",$I7,NA()) -> #N/A
A8: =TRIM(CLEAN(PROPER(peakflow_q1_2025_dirty!A6))) -> D-1152 | B8: =DATEVALUE(TRIM(CLEAN(peakflow_q1_2025_dirty!B6))) -> 45659 | C8: =TRIM(CLEAN(PROPER(peakflow_q1_2025_dirty!C6))) -> Catalyst Inc | D8: =TRIM(CLEAN(PROPER(peakflow_q1_2025_dirty!D6))) -> Starter Plan | E8: =TRIM(CLEAN(PROPER(peakflow_q1_2025_dirty!E6))) -> Elena Rossi | F8: =TRIM(CLEAN(PROPER(peakflow_q1_2025_dirty!F6))) -> Lukas Becker | G8: =TRIM(CLEAN(PROPER(peakflow_q1_2025_dirty!G6))) -> North America | H8: =VALUE(TRIM((CLEAN(peakflow_q1_2025_dirty!H6)))) -> 1 | I8: =VALUE(SUBSTITUTE(peakflow_q1_2025_dirty!I6,".","," )) -> 73.94 | J8: =H8*I8 -> 73.94 | K8: =TEXT(B8,"MMMM") -> Januar | M8: =IF($D8="Add-On: Analytics",$H8,NA()) -> #N/A | N8: =IF($D8="Add-On: Analytics",$I8,NA()) -> #N/A | O8: =IF($D8="Add-On: Support",$H8,NA()) -> #N/A | P8: =IF($D8="Add-On: Support",$I8,NA()) -> #N/A | Q8: =IF($D8="Business Plan",$H8,NA()) -> #N/A | R8: =IF($D8="Business Plan",$I8,NA()) -> #N/A | S8: =IF($D8="Enterprise Plan",$H8,NA()) -> #N/A | T8: =IF($D8="Enterprise Plan",$I8,NA()) -> #N/A | U8: =IF($D8="Pro Plan",$H8,NA()) -> #N/A | V8: =IF($D8="Pro Plan",$I8,NA()) -> #N/A | W8: =IF($D8="Starter Plan",$H8,NA()) -> 1 | X8: =IF($D8="Starter Plan",$I8,NA()) -> 73.94
A9: =TRIM(CLEAN(PROPER(peakflow_q1_2025_dirty!A7))) -> D-1202 | B9: =DATEVALUE(TRIM(CLEAN(peakflow_q1_2025_dirty!B7))) -> 45659 | C9: =TRIM(CLEAN(PROPER(peakflow_q1_2025_dirty!C7))) -> Nimbus Co | D9: =TRIM(CLEAN(PROPER(peakflow_q1_2025_dirty!D7))) -> Business Plan | E9: =TRIM(CLEAN(PROPER(peakflow_q1_2025_dirty!E7))) -> James Park | F9: =TRIM(CLEAN(PROPER(peakflow_q1_2025_dirty!F7))) -> Owen Walsh | G9: =TRIM(CLEAN(PROPER(peakflow_q1_2025_dirty!G7))) -> North America | H9: =VALUE(TRIM((CLEAN(peakflow_q1_2025_dirty!H7)))) -> 5 | I9: =VALUE(SUBSTITUTE(peakflow_q1_2025_dirty!I7,".","," )) -> 369.19 | J9: =H9*I9 -> 1845.95 | K9: =TEXT(B9,"MMMM") -> Januar | M9: =IF($D9="Add-On: Analytics",$H9,NA()) -> #N/A | N9: =IF($D9="Add-On: Analytics",$I9,NA()) -> #N/A | O9: =IF($D9="Add-On: Support",$H9,NA()) -> #N/A | P9: =IF($D9="Add-On: Support",$I9,NA()) -> #N/A | Q9: =IF($D9="Business Plan",$H9,NA()) -> 5 | R9: =IF($D9="Business Plan",$I9,NA()) -> 369.19 | S9: =IF($D9="Enterprise Plan",$H9,NA()) -> #N/A | T9: =IF($D9="Enterprise Plan",$I9,NA()) -> #N/A | U9: =IF($D9="Pro Plan",$H9,NA()) -> #N/A | V9: =IF($D9="Pro Plan",$I9,NA()) -> #N/A | W9: =IF($D9="Starter Plan",$H9,NA()) -> #N/A | X9: =IF($D9="Starter Plan",$I9,NA()) -> #N/A
A10: =TRIM(CLEAN(PROPER(peakflow_q1_2025_dirty!A8))) -> D-1249 | B10: =DATEVALUE(TRIM(CLEAN(peakflow_q1_2025_dirty!B8))) -> 45659 | C10: =TRIM(CLEAN(PROPER(peakflow_q1_2025_dirty!C8))) -> Summit Group | D10: =TRIM(CLEAN(PROPER(peakflow_q1_2025_dirty!D8))) -> Enterprise Plan | E10: =TRIM(CLEAN(PROPER(peakflow_q1_2025_dirty!E8))) -> Elena Rossi | F10: =TRIM(CLEAN(PROPER(peakflow_q1_2025_dirty!F8))) -> Lukas Becker | G10: =TRIM(CLEAN(PROPER(peakflow_q1_2025_dirty!G8))) -> North America | H10: =VALUE(TRIM((CLEAN(peakflow_q1_2025_dirty!H8)))) -> 1 | I10: =VALUE(SUBSTITUTE(peakflow_q1_2025_dirty!I8,".","," )) -> 1198.59 | J10: =H10*I10 -> 1198.59 | K10: =TEXT(B10,"MMMM") -> Januar | M10: =IF($D10="Add-On: Analytics",$H10,NA()) -> #N/A | N10: =IF($D10="Add-On: Analytics",$I10,NA()) -> #N/A | O10: =IF($D10="Add-On: Support",$H10,NA()) -> #N/A | P10: =IF($D10="Add-On: Support",$I10,NA()) -> #N/A | Q10: =IF($D10="Business Plan",$H10,NA()) -> #N/A | R10: =IF($D10="Business Plan",$I10,NA()) -> #N/A | S10: =IF($D10="Enterprise Plan",$H10,NA()) -> 1 | T10: =IF($D10="Enterprise Plan",$I10,NA()) -> 1198.59 | U10: =IF($D10="Pro Plan",$H10,NA()) -> #N/A | V10: =IF($D10="Pro Plan",$I10,NA()) -> #N/A | W10: =IF($D10="Starter Plan",$H10,NA()) -> #N/A | X10: =IF($D10="Starter Plan",$I10,NA()) -> #N/A
A11: =TRIM(CLEAN(PROPER(peakflow_q1_2025_dirty!A9))) -> D-1054 | B11: =DATEVALUE(TRIM(CLEAN(peakflow_q1_2025_dirty!B9))) -> 45661 | C11: =TRIM(CLEAN(PROPER(peakflow_q1_2025_dirty!C9))) -> Northwind Co | D11: =TRIM(CLEAN(PROPER(peakflow_q1_2025_dirty!D9))) -> Enterprise Plan | E11: =TRIM(CLEAN(PROPER(peakflow_q1_2025_dirty!E9))) -> David Kim | F11: =TRIM(CLEAN(PROPER(peakflow_q1_2025_dirty!F9))) -> Sarah Chen | G11: =TRIM(CLEAN(UPPER(peakflow_q1_2025_dirty!G9))) -> EMEA | H11: =VALUE(TRIM((CLEAN(peakflow_q1_2025_dirty!H9)))) -> 2 | I11: =VALUE(SUBSTITUTE(peakflow_q1_2025_dirty!I9,".","," )) -> 1182.78 | J11: =H11*I11 -> 2365.56 | K11: =TEXT(B11,"MMMM") -> Januar | M11: =IF($D11="Add-On: Analytics",$H11,NA()) -> #N/A | N11: =IF($D11="Add-On: Analytics",$I11,NA()) -> #N/A | O11: =IF($D11="Add-On: Support",$H11,NA()) -> #N/A | P11: =IF($D11="Add-On: Support",$I11,NA()) -> #N/A | Q11: =IF($D11="Business Plan",$H11,NA()) -> #N/A | R11: =IF($D11="Business Plan",$I11,NA()) -> #N/A | S11: =IF($D11="Enterprise Plan",$H11,NA()) -> 2 | T11: =IF($D11="Enterprise Plan",$I11,NA()) -> 1182.78 | U11: =IF($D11="Pro Plan",$H11,NA()) -> #N/A | V11: =IF($D11="Pro Plan",$I11,NA()) -> #N/A | W11: =IF($D11="Starter Plan",$H11,NA()) -> #N/A | X11: =IF($D11="Starter Plan",$I11,NA()) -> #N/A
A12: =TRIM(CLEAN(PROPER(peakflow_q1_2025_dirty!A10))) -> D-1102 | B12: =DATEVALUE(TRIM(CLEAN(peakflow_q1_2025_dirty!B10))) -> 45661 | C12: =TRIM(CLEAN(PROPER(peakflow_q1_2025_dirty!C10))) -> Lumen Labs | D12: =TRIM(CLEAN(PROPER(peakflow_q1_2025_dirty!D10))) -> Starter Plan | E12: =TRIM(CLEAN(PROPER(peakflow_q1_2025_dirty!E10))) -> Carlos Mendez | F12: =TRIM(CLEAN(PROPER(peakflow_q1_2025_dirty!F10))) -> Maya Rodriguez | G12: =TRIM(CLEAN(UPPER(peakflow_q1_2025_dirty!G10))) -> EMEA | H12: =VALUE(TRIM((CLEAN(peakflow_q1_2025_dirty!H10)))) -> 1 | I12: =VALUE(SUBSTITUTE(peakflow_q1_2025_dirty!I10,".","," )) -> 68.06 | J12: =H12*I12 -> 68.06 | K12: =TEXT(B12,"MMMM") -> Januar | M12: =IF($D12="Add-On: Analytics",$H12,NA()) -> #N/A | N12: =IF($D12="Add-On: Analytics",$I12,NA()) -> #N/A | O12: =IF($D12="Add-On: Support",$H12,NA()) -> #N/A | P12: =IF($D12="Add-On: Support",$I12,NA()) -> #N/A | Q12: =IF($D12="Business Plan",$H12,NA()) -> #N/A | R12: =IF($D12="Business Plan",$I12,NA()) -> #N/A | S12: =IF($D12="Enterprise Plan",$H12,NA()) -> #N/A | T12: =IF($D12="Enterprise Plan",$I12,NA()) -> #N/A | U12: =IF($D12="Pro Plan",$H12,NA()) -> #N/A | V12: =IF($D12="Pro Plan",$I12,NA()) -> #N/A | W12: =IF($D12="Starter Plan",$H12,NA()) -> 1 | X12: =IF($D12="Starter Plan",$I12,NA()) -> 68.06
A13: =TRIM(CLEAN(PROPER(peakflow_q1_2025_dirty!A11))) -> D-1115 | B13: =DATEVALUE(TRIM(CLEAN(peakflow_q1_2025_dirty!B11))) -> 45661 | C13: =TRIM(CLEAN(PROPER(peakflow_q1_2025_dirty!C11))) -> Kestrel Co | D13: =TRIM(CLEAN(PROPER(peakflow_q1_2025_dirty!D11))) -> Add-On: Support | E13: =TRIM(CLEAN(PROPER(peakflow_q1_2025_dirty!E11))) -> Tom Wilson | F13: =TRIM(CLEAN(PROPER(peakflow_q1_2025_dirty!F11))) -> Lukas Becker | G13: =TRIM(CLEAN(UPPER(peakflow_q1_2025_dirty!G11))) -> APAC | H13: =VALUE(TRIM((CLEAN(peakflow_q1_2025_dirty!H11)))) -> 2 | I13: =VALUE(SUBSTITUTE(peakflow_q1_2025_dirty!I11,".","," )) -> 118.97 | J13: =H13*I13 -> 237.94 | K13: =TEXT(B13,"MMMM") -> Januar | M13: =IF($D13="Add-On: Analytics",$H13,NA()) -> #N/A | N13: =IF($D13="Add-On: Analytics",$I13,NA()) -> #N/A | O13: =IF($D13="Add-On: Support",$H13,NA()) -> 2 | P13: =IF($D13="Add-On: Support",$I13,NA()) -> 118.97 | Q13: =IF($D13="Business Plan",$H13,NA()) -> #N/A | R13: =IF($D13="Business Plan",$I13,NA()) -> #N/A | S13: =IF($D13="Enterprise Plan",$H13,NA()) -> #N/A | T13: =IF($D13="Enterprise Plan",$I13,NA()) -> #N/A | U13: =IF($D13="Pro Plan",$H13,NA()) -> #N/A | V13: =IF($D13="Pro Plan",$I13,NA()) -> #N/A | W13: =IF($D13="Starter Plan",$H13,NA()) -> #N/A | X13: =IF($D13="Starter Plan",$I13,NA()) -> #N/A
A14: =TRIM(CLEAN(PROPER(peakflow_q1_2025_dirty!A12))) -> D-1138 | B14: =DATEVALUE(TRIM(CLEAN(peakflow_q1_2025_dirty!B12))) -> 45661 | C14: =TRIM(CLEAN(PROPER(peakflow_q1_2025_dirty!C12))) -> Nova Inc | D14: =TRIM(CLEAN(PROPER(peakflow_q1_2025_dirty!D12))) -> Starter Plan | E14: =TRIM(CLEAN(PROPER(peakflow_q1_2025_dirty!E12))) -> Marcus Johnson | F14: =TRIM(CLEAN(PROPER(peakflow_q1_2025_dirty!F12))) -> Sarah Chen | G14: =TRIM(CLEAN(UPPER(peakflow_q1_2025_dirty!G12))) -> LATAM | H14: =VALUE(TRIM((CLEAN(peakflow_q1_2025_dirty!H12)))) -> 5 | I14: =VALUE(SUBSTITUTE(peakflow_q1_2025_dirty!I12,".","," )) -> 53.28 | J14: =H14*I14 -> 266.4 | K14: =TEXT(B14,"MMMM") -> Januar | M14: =IF($D14="Add-On: Analytics",$H14,NA()) -> #N/A | N14: =IF($D14="Add-On: Analytics",$I14,NA()) -> #N/A | O14: =IF($D14="Add-On: Support",$H14,NA()) -> #N/A | P14: =IF($D14="Add-On: Support",$I14,NA()) -> #N/A | Q14: =IF($D14="Business Plan",$H14,NA()) -> #N/A | R14: =IF($D14="Business Plan",$I14,NA()) -> #N/A | S14: =IF($D14="Enterprise Plan",$H14,NA()) -> #N/A | T14: =IF($D14="Enterprise Plan",$I14,NA()) -> #N/A | U14: =IF($D14="Pro Plan",$H14,NA()) -> #N/A | V14: =IF($D14="Pro Plan",$I14,NA()) -> #N/A | W14: =IF($D14="Starter Plan",$H14,NA()) -> 5 | X14: =IF($D14="Starter Plan",$I14,NA()) -> 53.28
A15: =TRIM(CLEAN(PROPER(peakflow_q1_2025_dirty!A13))) -> D-1231 | B15: =DATEVALUE(TRIM(CLEAN(peakflow_q1_2025_dirty!B13))) -> 45661 | C15: =TRIM(CLEAN(PROPER(peakflow_q1_2025_dirty!C13))) -> Borealis Co | D15: =TRIM(CLEAN(PROPER(peakflow_q1_2025_dirty!D13))) -> Enterprise Plan | E15: =TRIM(CLEAN(PROPER(peakflow_q1_2025_dirty!E13))) -> Marcus Johnson | F15: =TRIM(CLEAN(PROPER(peakflow_q1_2025_dirty!F13))) -> Sarah Chen | G15: =TRIM(CLEAN(UPPER(peakflow_q1_2025_dirty!G13))) -> EMEA | H15: =VALUE(TRIM((CLEAN(peakflow_q1_2025_dirty!H13)))) -> 1 | I15: =VALUE(SUBSTITUTE(peakflow_q1_2025_dirty!I13,".","," )) -> 992.76 | J15: =H15*I15 -> 992.76 | K15: =TEXT(B15,"MMMM") -> Januar | M15: =IF($D15="Add-On: Analytics",$H15,NA()) -> #N/A | N15: =IF($D15="Add-On: Analytics",$I15,NA()) -> #N/A | O15: =IF($D15="Add-On: Support",$H15,NA()) -> #N/A | P15: =IF($D15="Add-On: Support",$I15,NA()) -> #N/A | Q15: =IF($D15="Business Plan",$H15,NA()) -> #N/A | R15: =IF($D15="Business Plan",$I15,NA()) -> #N/A | S15: =IF($D15="Enterprise Plan",$H15,NA()) -> 1 | T15: =IF($D15="Enterprise Plan",$I15,NA()) -> 992.76 | U15: =IF($D15="Pro Plan",$H15,NA()) -> #N/A | V15: =IF($D15="Pro Plan",$I15,NA()) -> #N/A | W15: =IF($D15="Starter Plan",$H15,NA()) -> #N/A | X15: =IF($D15="Starter Plan",$I15,NA()) -> #N/A
A16: =TRIM(CLEAN(PROPER(peakflow_q1_2025_dirty!A14))) -> D-1008 | B16: =DATEVALUE(TRIM(CLEAN(peakflow_q1_2025_dirty!B14))) -> 45662 | C16: =TRIM(CLEAN(PROPER(peakflow_q1_2025_dirty!C14))) -> Phoenix Co | D16: =TRIM(CLEAN(PROPER(peakflow_q1_2025_dirty!D14))) -> Pro Plan | E16: =TRIM(CLEAN(PROPER(peakflow_q1_2025_dirty!E14))) -> Tom Wilson | F16: =TRIM(CLEAN(PROPER(peakflow_q1_2025_dirty!F14))) -> Lukas Becker | G16: =TRIM(CLEAN(UPPER(peakflow_q1_2025_dirty!G14))) -> LATAM | H16: =VALUE(TRIM((CLEAN(peakflow_q1_2025_dirty!H14)))) -> 20 | I16: =VALUE(SUBSTITUTE(peakflow_q1_2025_dirty!I14,".","," )) -> 249.04 | J16: =H16*I16 -> 4980.8 | K16: =TEXT(B16,"MMMM") -> Januar | M16: =IF($D16="Add-On: Analytics",$H16,NA()) -> #N/A | N16: =IF($D16="Add-On: Analytics",$I16,NA()) -> #N/A | O16: =IF($D16="Add-On: Support",$H16,NA()) -> #N/A | P16: =IF($D16="Add-On: Support",$I16,NA()) -> #N/A | Q16: =IF($D16="Business Plan",$H16,NA()) -> #N/A | R16: =IF($D16="Business Plan",$I16,NA()) -> #N/A | S16: =IF($D16="Enterprise Plan",$H16,NA()) -> #N/A | T16: =IF($D16="Enterprise Plan",$I16,NA()) -> #N/A | U16: =IF($D16="Pro Plan",$H16,NA()) -> 20 | V16: =IF($D16="Pro Plan",$I16,NA()) -> 249.04 | W16: =IF($D16="Starter Plan",$H16,NA()) -> #N/A | X16: =IF($D16="Starter Plan",$I16,NA()) -> #N/A
A17: =TRIM(CLEAN(PROPER(peakflow_q1_2025_dirty!A15))) -> D-1071 | B17: =DATEVALUE(TRIM(CLEAN(peakflow_q1_2025_dirty!B15))) -> 45662 | C17: =TRIM(CLEAN(PROPER(peakflow_q1_2025_dirty!C15))) -> Apex Group | D17: =TRIM(CLEAN(PROPER(peakflow_q1_2025_dirty!D15))) -> Business Plan | E17: =TRIM(CLEAN(PROPER(peakflow_q1_2025_dirty!E15))) -> David Kim | F17: =TRIM(CLEAN(PROPER(peakflow_q1_2025_dirty!F15))) -> Sarah Chen | G17: =TRIM(CLEAN(UPPER(peakflow_q1_2025_dirty!G15))) -> APAC | H17: =VALUE(TRIM((CLEAN(peakflow_q1_2025_dirty!H15)))) -> 1 | I17: =VALUE(SUBSTITUTE(peakflow_q1_2025_dirty!I15,".","," )) -> 386.52 | J17: =H17*I17 -> 386.52 | K17: =TEXT(B17,"MMMM") -> Januar | M17: =IF($D17="Add-On: Analytics",$H17,NA()) -> #N/A | N17: =IF($D17="Add-On: Analytics",$I17,NA()) -> #N/A | O17: =IF($D17="Add-On: Support",$H17,NA()) -> #N/A | P17: =IF($D17="Add-On: Support",$I17,NA()) -> #N/A | Q17: =IF($D17="Business Plan",$H17,NA()) -> 1 | R17: =IF($D17="Business Plan",$I17,NA()) -> 386.52 | S17: =IF($D17="Enterprise Plan",$H17,NA()) -> #N/A | T17: =IF($D17="Enterprise Plan",$I17,NA()) -> #N/A | U17: =IF($D17="Pro Plan",$H17,NA()) -> #N/A | V17: =IF($D17="Pro Plan",$I17,NA()) -> #N/A | W17: =IF($D17="Starter Plan",$H17,NA()) -> #N/A | X17: =IF($D17="Starter Plan",$I17,NA()) -> #N/A
A18: =TRIM(CLEAN(PROPER(peakflow_q1_2025_dirty!A16))) -> D-1105 | B18: =DATEVALUE(TRIM(CLEAN(peakflow_q1_2025_dirty!B16))) -> 45662 | C18: =TRIM(CLEAN(PROPER(peakflow_q1_2025_dirty!C16))) -> Kestrel Co | D18: =TRIM(CLEAN(PROPER(peakflow_q1_2025_dirty!D16))) -> Pro Plan | E18: =TRIM(CLEAN(PROPER(peakflow_q1_2025_dirty!E16))) -> Elena Rossi | F18: =TRIM(CLEAN(PROPER(peakflow_q1_2025_dirty!F16))) -> Lukas Becker | G18: =TRIM(CLEAN(PROPER(peakflow_q1_2025_dirty!G16))) -> North America | H18: =VALUE(TRIM((CLEAN(peakflow_q1_2025_dirty!H16)))) -> 1 | I18: =VALUE(SUBSTITUTE(peakflow_q1_2025_dirty!I16,".","," )) -> 226.12 | J18: =H18*I18 -> 226.12 | K18: =TEXT(B18,"MMMM") -> Januar | M18: =IF($D18="Add-On: Analytics",$H18,NA()) -> #N/A | N18: =IF($D18="Add-On: Analytics",$I18,NA()) -> #N/A | O18: =IF($D18="Add-On: Support",$H18,NA()) -> #N/A | P18: =IF($D18="Add-On: Support",$I18,NA()) -> #N/A | Q18: =IF($D18="Business Plan",$H18,NA()) -> #N/A | R18: =IF($D18="Business Plan",$I18,NA()) -> #N/A | S18: =IF($D18="Enterprise Plan",$H18,NA()) -> #N/A | T18: =IF($D18="Enterprise Plan",$I18,NA()) -> #N/A | U18: =IF($D18="Pro Plan",$H18,NA()) -> 1 | V18: =IF($D18="Pro Plan",$I18,NA()) -> 226.12 | W18: =IF($D18="Starter Plan",$H18,NA()) -> #N/A | X18: =IF($D18="Starter Plan",$I18,NA()) -> #N/A
A19: =TRIM(CLEAN(PROPER(peakflow_q1_2025_dirty!A17))) -> D-1110 | B19: =DATEVALUE(TRIM(CLEAN(peakflow_q1_2025_dirty!B17))) -> 45662 | C19: =TRIM(CLEAN(PROPER(peakflow_q1_2025_dirty!C17))) -> Rivet Co | D19: =TRIM(CLEAN(PROPER(peakflow_q1_2025_dirty!D17))) -> Starter Plan | E19: =TRIM(CLEAN(PROPER(peakflow_q1_2025_dirty!E17))) -> James Park | F19: =TRIM(CLEAN(PROPER(peakflow_q1_2025_dirty!F17))) -> Owen Walsh | G19: =TRIM(CLEAN(UPPER(peakflow_q1_2025_dirty!G17))) -> LATAM | H19: =VALUE(TRIM((CLEAN(peakflow_q1_2025_dirty!H17)))) -> 1 | I19: =VALUE(SUBSTITUTE(peakflow_q1_2025_dirty!I17,".","," )) -> 73.28 | J19: =H19*I19 -> 73.28 | K19: =TEXT(B19,"MMMM") -> Januar | M19: =IF($D19="Add-On: Analytics",$H19,NA()) -> #N/A | N19: =IF($D19="Add-On: Analytics",$I19,NA()) -> #N/A | O19: =IF($D19="Add-On: Support",$H19,NA()) -> #N/A | P19: =IF($D19="Add-On: Support",$I19,NA()) -> #N/A | Q19: =IF($D19="Business Plan",$H19,NA()) -> #N/A | R19: =IF($D19="Business Plan",$I19,NA()) -> #N/A | S19: =IF($D19="Enterprise Plan",$H19,NA()) -> #N/A | T19: =IF($D19="Enterprise Plan",$I19,NA()) -> #N/A | U19: =IF($D19="Pro Plan",$H19,NA()) -> #N/A | V19: =IF($D19="Pro Plan",$I19,NA()) -> #N/A | W19: =IF($D19="Starter Plan",$H19,NA()) -> 1 | X19: =IF($D19="Starter Plan",$I19,NA()) -> 73.28
A20: =TRIM(CLEAN(PROPER(peakflow_q1_2025_dirty!A18))) -> D-1112 | B20: =DATEVALUE(TRIM(CLEAN(peakflow_q1_2025_dirty!B18))) -> 45662 | C20: =TRIM(CLEAN(PROPER(peakflow_q1_2025_dirty!C18))) -> Borealis Co | D20: =TRIM(CLEAN(PROPER(peakflow_q1_2025_dirty!D18))) -> Starter Plan | E20: =TRIM(CLEAN(PROPER(peakflow_q1_2025_dirty!E18))) -> Hannah Lee | F20: =TRIM(CLEAN(PROPER(peakflow_q1_2025_dirty!F18))) -> Owen Walsh | G20: =TRIM(CLEAN(UPPER(peakflow_q1_2025_dirty!G18))) -> EMEA | H20: =VALUE(TRIM((CLEAN(peakflow_q1_2025_dirty!H18)))) -> 5 | I20: =VALUE(SUBSTITUTE(peakflow_q1_2025_dirty!I18,".","," )) -> 45.99 | J20: =H20*I20 -> 229.95 | K20: =TEXT(B20,"MMMM") -> Januar | M20: =IF($D20="Add-On: Analytics",$H20,NA()) -> #N/A | N20: =IF($D20="Add-On: Analytics",$I20,NA()) -> #N/A | O20: =IF($D20="Add-On: Support",$H20,NA()) -> #N/A | P20: =IF($D20="Add-On: Support",$I20,NA()) -> #N/A | Q20: =IF($D20="Business Plan",$H20,NA()) -> #N/A | R20: =IF($D20="Business Plan",$I20,NA()) -> #N/A | S20: =IF($D20="Enterprise Plan",$H20,NA()) -> #N/A | T20: =IF($D20="Enterprise Plan",$I20,NA()) -> #N/A | U20: =IF($D20="Pro Plan",$H20,NA()) -> #N/A | V20: =IF($D20="Pro Plan",$I20,NA()) -> #N/A | W20: =IF($D20="Starter Plan",$H20,NA()) -> 5 | X20: =IF($D20="Starter Plan",$I20,NA()) -> 45.99
A21: =TRIM(CLEAN(PROPER(peakflow_q1_2025_dirty!A19))) -> D-1132 | B21: =DATEVALUE(TRIM(CLEAN(peakflow_q1_2025_dirty!B19))) -> 45662 | C21: =TRIM(CLEAN(PROPER(peakflow_q1_2025_dirty!C19))) -> Quanta Labs | D21: =TRIM(CLEAN(PROPER(peakflow_q1_2025_dirty!D19))) -> Starter Plan | E21: =TRIM(CLEAN(PROPER(peakflow_q1_2025_dirty!E19))) -> Hannah Lee | F21: =TRIM(CLEAN(PROPER(peakflow_q1_2025_dirty!F19))) -> Owen Walsh | G21: =TRIM(CLEAN(UPPER(peakflow_q1_2025_dirty!G19))) -> APAC | H21: =VALUE(TRIM((CLEAN(peakflow_q1_2025_dirty!H19)))) -> 50 | I21: =VALUE(SUBSTITUTE(peakflow_q1_2025_dirty!I19,".","," )) -> 70.68 | J21: =H21*I21 -> 3534 | K21: =TEXT(B21,"MMMM") -> Januar | M21: =IF($D21="Add-On: Analytics",$H21,NA()) -> #N/A | N21: =IF($D21="Add-On: Analytics",$I21,NA()) -> #N/A | O21: =IF($D21="Add-On: Support",$H21,NA()) -> #N/A | P21: =IF($D21="Add-On: Support",$I21,NA()) -> #N/A | Q21: =IF($D21="Business Plan",$H21,NA()) -> #N/A | R21: =IF($D21="Business Plan",$I21,NA()) -> #N/A | S21: =IF($D21="Enterprise Plan",$H21,NA()) -> #N/A | T21: =IF($D21="Enterprise Plan",$I21,NA()) -> #N/A | U21: =IF($D21="Pro Plan",$H21,NA()) -> #N/A | V21: =IF($D21="Pro Plan",$I21,NA()) -> #N/A | W21: =IF($D21="Starter Plan",$H21,NA()) -> 50 | X21: =IF($D21="Starter Plan",$I21,NA()) -> 70.68
A22: =TRIM(CLEAN(PROPER(peakflow_q1_2025_dirty!A20))) -> D-1150 | B22: =DATEVALUE(TRIM(CLEAN(peakflow_q1_2025_dirty!B20))) -> 45662 | C22: =TRIM(CLEAN(PROPER(peakflow_q1_2025_dirty!C20))) -> Nimbus Co | D22: =TRIM(CLEAN(PROPER(peakflow_q1_2025_dirty!D20))) -> Pro Plan | E22: =TRIM(CLEAN(PROPER(peakflow_q1_2025_dirty!E20))) -> James Park | F22: =TRIM(CLEAN(PROPER(peakflow_q1_2025_dirty!F20))) -> Owen Walsh | G22: =TRIM(CLEAN(UPPER(peakflow_q1_2025_dirty!G20))) -> EMEA | H22: =VALUE(TRIM((CLEAN(peakflow_q1_2025_dirty!H20)))) -> 20 | I22: =VALUE(SUBSTITUTE(peakflow_q1_2025_dirty!I20,".","," )) -> 192.21 | J22: =H22*I22 -> 3844.2 | K22: =TEXT(B22,"MMMM") -> Januar | M22: =IF($D22="Add-On: Analytics",$H22,NA()) -> #N/A | N22: =IF($D22="Add-On: Analytics",$I22,NA()) -> #N/A | O22: =IF($D22="Add-On: Support",$H22,NA()) -> #N/A | P22: =IF($D22="Add-On: Support",$I22,NA()) -> #N/A | Q22: =IF($D22="Business Plan",$H22,NA()) -> #N/A | R22: =IF($D22="Business Plan",$I22,NA()) -> #N/A | S22: =IF($D22="Enterprise Plan",$H22,NA()) -> #N/A | T22: =IF($D22="Enterprise Plan",$I22,NA()) -> #N/A | U22: =IF($D22="Pro Plan",$H22,NA()) -> 20 | V22: =IF($D22="Pro Plan",$I22,NA()) -> 192.21 | W22: =IF($D22="Starter Plan",$H22,NA()) -> #N/A | X22: =IF($D22="Starter Plan",$I22,NA()) -> #N/A
A23: =TRIM(CLEAN(PROPER(peakflow_q1_2025_dirty!A21))) -> D-1194 | B23: =DATEVALUE(TRIM(CLEAN(peakflow_q1_2025_dirty!B21))) -> 45662 | C23: =TRIM(CLEAN(PROPER(peakflow_q1_2025_dirty!C21))) -> Onyx Group | D23: =TRIM(CLEAN(PROPER(peakflow_q1_2025_dirty!D21))) -> Pro Plan | E23: =TRIM(CLEAN(PROPER(peakflow_q1_2025_dirty!E21))) -> Sophie Laurent | F23: =TRIM(CLEAN(PROPER(peakflow_q1_2025_dirty!F21))) -> Maya Rodriguez | G23: =TRIM(CLEAN(PROPER(peakflow_q1_2025_dirty!G21))) -> North America | H23: =VALUE(TRIM((CLEAN(peakflow_q1_2025_dirty!H21)))) -> 2 | I23: =VALUE(SUBSTITUTE(peakflow_q1_2025_dirty!I21,".","," )) -> 193.5 | J23: =H23*I23 -> 387 | K23: =TEXT(B23,"MMMM") -> Januar | M23: =IF($D23="Add-On: Analytics",$H23,NA()) -> #N/A | N23: =IF($D23="Add-On: Analytics",$I23,NA()) -> #N/A | O23: =IF($D23="Add-On: Support",$H23,NA()) -> #N/A | P23: =IF($D23="Add-On: Support",$I23,NA()) -> #N/A | Q23: =IF($D23="Business Plan",$H23,NA()) -> #N/A | R23: =IF($D23="Business Plan",$I23,NA()) -> #N/A | S23: =IF($D23="Enterprise Plan",$H23,NA()) -> #N/A | T23: =IF($D23="Enterprise Plan",$I23,NA()) -> #N/A | U23: =IF($D23="Pro Plan",$H23,NA()) -> 2 | V23: =IF($D23="Pro Plan",$I23,NA()) -> 193.5 | W23: =IF($D23="Starter Plan",$H23,NA()) -> #N/A | X23: =IF($D23="Starter Plan",$I23,NA()) -> #N/A
A24: =TRIM(CLEAN(PROPER(peakflow_q1_2025_dirty!A22))) -> D-1091 | B24: =DATEVALUE(TRIM(CLEAN(peakflow_q1_2025_dirty!B22))) -> 45663 | C24: =TRIM(CLEAN(PROPER(peakflow_q1_2025_dirty!C22))) -> Fusion Group | D24: =TRIM(CLEAN(PROPER(peakflow_q1_2025_dirty!D22))) -> Starter Plan | E24: =TRIM(CLEAN(PROPER(peakflow_q1_2025_dirty!E22))) -> Marcus Johnson | F24: =TRIM(CLEAN(PROPER(peakflow_q1_2025_dirty!F22))) -> Sarah Chen | G24: =TRIM(CLEAN(UPPER(peakflow_q1_2025_dirty!G22))) -> APAC | H24: =VALUE(TRIM((CLEAN(peakflow_q1_2025_dirty!H22)))) -> 1 | I24: =VALUE(SUBSTITUTE(peakflow_q1_2025_dirty!I22,".","," )) -> 53.39 | J24: =H24*I24 -> 53.39 | K24: =TEXT(B24,"MMMM") -> Januar | M24: =IF($D24="Add-On: Analytics",$H24,NA()) -> #N/A | N24: =IF($D24="Add-On: Analytics",$I24,NA()) -> #N/A | O24: =IF($D24="Add-On: Support",$H24,NA()) -> #N/A | P24: =IF($D24="Add-On: Support",$I24,NA()) -> #N/A | Q24: =IF($D24="Business Plan",$H24,NA()) -> #N/A | R24: =IF($D24="Business Plan",$I24,NA()) -> #N/A | S24: =IF($D24="Enterprise Plan",$H24,NA()) -> #N/A | T24: =IF($D24="Enterprise Plan",$I24,NA()) -> #N/A | U24: =IF($D24="Pro Plan",$H24,NA()) -> #N/A | V24: =IF($D24="Pro Plan",$I24,NA()) -> #N/A | W24: =IF($D24="Starter Plan",$H24,NA()) -> 1 | X24: =IF($D24="Starter Plan",$I24,NA()) -> 53.39
A25: =TRIM(CLEAN(PROPER(peakflow_q1_2025_dirty!A23))) -> D-1092 | B25: =DATEVALUE(TRIM(CLEAN(peakflow_q1_2025_dirty!B23))) -> 45663 | C25: =TRIM(CLEAN(PROPER(peakflow_q1_2025_dirty!C23))) -> Summit Group | D25: =TRIM(CLEAN(PROPER(peakflow_q1_2025_dirty!D23))) -> Pro Plan | E25: =TRIM(CLEAN(PROPER(peakflow_q1_2025_dirty!E23))) -> Carlos Mendez | F25: =TRIM(CLEAN(PROPER(peakflow_q1_2025_dirty!F23))) -> Maya Rodriguez | G25: =TRIM(CLEAN(UPPER(peakflow_q1_2025_dirty!G23))) -> APAC | H25: =VALUE(TRIM((CLEAN(peakflow_q1_2025_dirty!H23)))) -> 1 | I25: =VALUE(SUBSTITUTE(peakflow_q1_2025_dirty!I23,".","," )) -> 202.22 | J25: =H25*I25 -> 202.22 | K25: =TEXT(B25,"MMMM") -> Januar | M25: =IF($D25="Add-On: Analytics",$H25,NA()) -> #N/A | N25: =IF($D25="Add-On: Analytics",$I25,NA()) -> #N/A | O25: =IF($D25="Add-On: Support",$H25,NA()) -> #N/A | P25: =IF($D25="Add-On: Support",$I25,NA()) -> #N/A | Q25: =IF($D25="Business Plan",$H25,NA()) -> #N/A | R25: =IF($D25="Business Plan",$I25,NA()) -> #N/A | S25: =IF($D25="Enterprise Plan",$H25,NA()) -> #N/A | T25: =IF($D25="Enterprise Plan",$I25,NA()) -> #N/A | U25: =IF($D25="Pro Plan",$H25,NA()) -> 1 | V25: =IF($D25="Pro Plan",$I25,NA()) -> 202.22 | W25: =IF($D25="Starter Plan",$H25,NA()) -> #N/A | X25: =IF($D25="Starter Plan",$I25,NA()) -> #N/A
A26: =TRIM(CLEAN(PROPER(peakflow_q1_2025_dirty!A24))) -> D-1211 | B26: =DATEVALUE(TRIM(CLEAN(peakflow_q1_2025_dirty!B24))) -> 45663 | C26: =TRIM(CLEAN(PROPER(peakflow_q1_2025_dirty!C24))) -> Apex Group | D26: =TRIM(CLEAN(PROPER(peakflow_q1_2025_dirty!D24))) -> Add-On: Analytics | E26: =TRIM(CLEAN(PROPER(peakflow_q1_2025_dirty!E24))) -> James Park | F26: =TRIM(CLEAN(PROPER(peakflow_q1_2025_dirty!F24))) -> Owen Walsh | G26: =TRIM(CLEAN(UPPER(peakflow_q1_2025_dirty!G24))) -> LATAM | H26: =VALUE(TRIM((CLEAN(peakflow_q1_2025_dirty!H24)))) -> 5 | I26: =VALUE(SUBSTITUTE(peakflow_q1_2025_dirty!I24,".","," )) -> 69.69 | J26: =H26*I26 -> 348.45 | K26: =TEXT(B26,"MMMM") -> Januar | M26: =IF($D26="Add-On: Analytics",$H26,NA()) -> 5 | N26: =IF($D26="Add-On: Analytics",$I26,NA()) -> 69.69 | O26: =IF($D26="Add-On: Support",$H26,NA()) -> #N/A | P26: =IF($D26="Add-On: Support",$I26,NA()) -> #N/A | Q26: =IF($D26="Business Plan",$H26,NA()) -> #N/A | R26: =IF($D26="Business Plan",$I26,NA()) -> #N/A | S26: =IF($D26="Enterprise Plan",$H26,NA()) -> #N/A | T26: =IF($D26="Enterprise Plan",$I26,NA()) -> #N/A | U26: =IF($D26="Pro Plan",$H26,NA()) -> #N/A | V26: =IF($D26="Pro Plan",$I26,NA()) -> #N/A | W26: =IF($D26="Starter Plan",$H26,NA()) -> #N/A | X26: =IF($D26="Starter Plan",$I26,NA()) -> #N/A
A27: =TRIM(CLEAN(PROPER(peakflow_q1_2025_dirty!A25))) -> D-1063 | B27: =DATEVALUE(TRIM(CLEAN(peakflow_q1_2025_dirty!B25))) -> 45664 | C27: =TRIM(CLEAN(PROPER(peakflow_q1_2025_dirty!C25))) -> Granite Co | D27: =TRIM(CLEAN(PROPER(peakflow_q1_2025_dirty!D25))) -> Add-On: Support | E27: =TRIM(CLEAN(PROPER(peakflow_q1_2025_dirty!E25))) -> Marcus Johnson | F27: =TRIM(CLEAN(PROPER(peakflow_q1_2025_dirty!F25))) -> Sarah Chen | G27: =TRIM(CLEAN(PROPER(peakflow_q1_2025_dirty!G25))) -> North America | H27: =VALUE(TRIM((CLEAN(peakflow_q1_2025_dirty!H25)))) -> 1 | I27: =VALUE(SUBSTITUTE(peakflow_q1_2025_dirty!I25,".","," )) -> 93.27 | J27: =H27*I27 -> 93.27 | K27: =TEXT(B27,"MMMM") -> Januar | M27: =IF($D27="Add-On: Analytics",$H27,NA()) -> #N/A | N27: =IF($D27="Add-On: Analytics",$I27,NA()) -> #N/A | O27: =IF($D27="Add-On: Support",$H27,NA()) -> 1 | P27: =IF($D27="Add-On: Support",$I27,NA()) -> 93.27 | Q27: =IF($D27="Business Plan",$H27,NA()) -> #N/A | R27: =IF($D27="Business Plan",$I27,NA()) -> #N/A | S27: =IF($D27="Enterprise Plan",$H27,NA()) -> #N/A | T27: =IF($D27="Enterprise Plan",$I27,NA()) -> #N/A | U27: =IF($D27="Pro Plan",$H27,NA()) -> #N/A | V27: =IF($D27="Pro Plan",$I27,NA()) -> #N/A | W27: =IF($D27="Starter Plan",$H27,NA()) -> #N/A | X27: =IF($D27="Starter Plan",$I27,NA()) -> #N/A
A28: =TRIM(CLEAN(PROPER(peakflow_q1_2025_dirty!A26))) -> D-1206 | B28: =DATEVALUE(TRIM(CLEAN(peakflow_q1_2025_dirty!B26))) -> 45664 | C28: =TRIM(CLEAN(PROPER(peakflow_q1_2025_dirty!C26))) -> Stellar Co | D28: =TRIM(CLEAN(PROPER(peakflow_q1_2025_dirty!D26))) -> Add-On: Analytics | E28: =TRIM(CLEAN(PROPER(peakflow_q1_2025_dirty!E26))) -> Elena Rossi | F28: =TRIM(CLEAN(PROPER(peakflow_q1_2025_dirty!F26))) -> Lukas Becker | G28: =TRIM(CLEAN(UPPER(peakflow_q1_2025_dirty!G26))) -> APAC | H28: =VALUE(TRIM((CLEAN(peakflow_q1_2025_dirty!H26)))) -> 5 | I28: =VALUE(SUBSTITUTE(peakflow_q1_2025_dirty!I26,".","," )) -> 74.69 | J28: =H28*I28 -> 373.45 | K28: =TEXT(B28,"MMMM") -> Januar | M28: =IF($D28="Add-On: Analytics",$H28,NA()) -> 5 | N28: =IF($D28="Add-On: Analytics",$I28,NA()) -> 74.69 | O28: =IF($D28="Add-On: Support",$H28,NA()) -> #N/A | P28: =IF($D28="Add-On: Support",$I28,NA()) -> #N/A | Q28: =IF($D28="Business Plan",$H28,NA()) -> #N/A | R28: =IF($D28="Business Plan",$I28,NA()) -> #N/A | S28: =IF($D28="Enterprise Plan",$H28,NA()) -> #N/A | T28: =IF($D28="Enterprise Plan",$I28,NA()) -> #N/A | U28: =IF($D28="Pro Plan",$H28,NA()) -> #N/A | V28: =IF($D28="Pro Plan",$I28,NA()) -> #N/A | W28: =IF($D28="Starter Plan",$H28,NA()) -> #N/A | X28: =IF($D28="Starter Plan",$I28,NA()) -> #N/A
A29: =TRIM(CLEAN(PROPER(peakflow_q1_2025_dirty!A27))) -> D-1123 | B29: =DATEVALUE(TRIM(CLEAN(peakflow_q1_2025_dirty!B27))) -> 45665 | C29: =TRIM(CLEAN(PROPER(peakflow_q1_2025_dirty!C27))) -> Nimbus Co | D29: =TRIM(CLEAN(PROPER(peakflow_q1_2025_dirty!D27))) -> Add-On: Support | E29: =TRIM(CLEAN(PROPER(peakflow_q1_2025_dirty!E27))) -> Tom Wilson | F29: =TRIM(CLEAN(PROPER(peakflow_q1_2025_dirty!F27))) -> Lukas Becker | G29: =TRIM(CLEAN(UPPER(peakflow_q1_2025_dirty!G27))) -> LATAM | H29: =VALUE(TRIM((CLEAN(peakflow_q1_2025_dirty!H27)))) -> 1 | I29: =VALUE(SUBSTITUTE(peakflow_q1_2025_dirty!I27,".","," )) -> 92.92 | J29: =H29*I29 -> 92.92 | K29: =TEXT(B29,"MMMM") -> Januar | M29: =IF($D29="Add-On: Analytics",$H29,NA()) -> #N/A | N29: =IF($D29="Add-On: Analytics",$I29,NA()) -> #N/A | O29: =IF($D29="Add-On: Support",$H29,NA()) -> 1 | P29: =IF($D29="Add-On: Support",$I29,NA()) -> 92.92 | Q29: =IF($D29="Business Plan",$H29,NA()) -> #N/A | R29: =IF($D29="Business Plan",$I29,NA()) -> #N/A | S29: =IF($D29="Enterprise Plan",$H29,NA()) -> #N/A | T29: =IF($D29="Enterprise Plan",$I29,NA()) -> #N/A | U29: =IF($D29="Pro Plan",$H29,NA()) -> #N/A | V29: =IF($D29="Pro Plan",$I29,NA()) -> #N/A | W29: =IF($D29="Starter Plan",$H29,NA()) -> #N/A | X29: =IF($D29="Starter Plan",$I29,NA()) -> #N/A
A30: =TRIM(CLEAN(PROPER(peakflow_q1_2025_dirty!A28))) -> D-1121 | B30: =DATEVALUE(TRIM(CLEAN(peakflow_q1_2025_dirty!B28))) -> 45666 | C30: =TRIM(CLEAN(PROPER(peakflow_q1_2025_dirty!C28))) -> Nova Inc | D30: =TRIM(CLEAN(PROPER(peakflow_q1_2025_dirty!D28))) -> Enterprise Plan | E30: =TRIM(CLEAN(PROPER(peakflow_q1_2025_dirty!E28))) -> Priya Patel | F30: =TRIM(CLEAN(PROPER(peakflow_q1_2025_dirty!F28))) -> Maya Rodriguez | G30: =TRIM(CLEAN(UPPER(peakflow_q1_2025_dirty!G28))) -> APAC | H30: =VALUE(TRIM((CLEAN(peakflow_q1_2025_dirty!H28)))) -> 1 | I30: =VALUE(SUBSTITUTE(peakflow_q1_2025_dirty!I28,".","," )) -> 1388.69 | J30: =H30*I30 -> 1388.69 | K30: =TEXT(B30,"MMMM") -> Januar | M30: =IF($D30="Add-On: Analytics",$H30,NA()) -> #N/A | N30: =IF($D30="Add-On: Analytics",$I30,NA()) -> #N/A | O30: =IF($D30="Add-On: Support",$H30,NA()) -> #N/A | P30: =IF($D30="Add-On: Support",$I30,NA()) -> #N/A | Q30: =IF($D30="Business Plan",$H30,NA()) -> #N/A | R30: =IF($D30="Business Plan",$I30,NA()) -> #N/A | S30: =IF($D30="Enterprise Plan",$H30,NA()) -> 1 | T30: =IF($D30="Enterprise Plan",$I30,NA()) -> 1388.69 | U30: =IF($D30="Pro Plan",$H30,NA()) -> #N/A | V30: =IF($D30="Pro Plan",$I30,NA()) -> #N/A | W30: =IF($D30="Starter Plan",$H30,NA()) -> #N/A | X30: =IF($D30="Starter Plan",$I30,NA()) -> #N/A
A31: =TRIM(CLEAN(PROPER(peakflow_q1_2025_dirty!A29))) -> D-1029 | B31: =DATEVALUE(TRIM(CLEAN(peakflow_q1_2025_dirty!B29))) -> 45667 | C31: =TRIM(CLEAN(PROPER(peakflow_q1_2025_dirty!C29))) -> Cascade Group | D31: =TRIM(CLEAN(PROPER(peakflow_q1_2025_dirty!D29))) -> Starter Plan | E31: =TRIM(CLEAN(PROPER(peakflow_q1_2025_dirty!E29))) -> Sophie Laurent | F31: =TRIM(CLEAN(PROPER(peakflow_q1_2025_dirty!F29))) -> Maya Rodriguez | G31: =TRIM(CLEAN(UPPER(peakflow_q1_2025_dirty!G29))) -> APAC | H31: =VALUE(TRIM((CLEAN(peakflow_q1_2025_dirty!H29)))) -> 50 | I31: =VALUE(SUBSTITUTE(peakflow_q1_2025_dirty!I29,".","," )) -> 72.26 | J31: =H31*I31 -> 3613 | K31: =TEXT(B31,"MMMM") -> Januar | M31: =IF($D31="Add-On: Analytics",$H31,NA()) -> #N/A | N31: =IF($D31="Add-On: Analytics",$I31,NA()) -> #N/A | O31: =IF($D31="Add-On: Support",$H31,NA()) -> #N/A | P31: =IF($D31="Add-On: Support",$I31,NA()) -> #N/A | Q31: =IF($D31="Business Plan",$H31,NA()) -> #N/A | R31: =IF($D31="Business Plan",$I31,NA()) -> #N/A | S31: =IF($D31="Enterprise Plan",$H31,NA()) -> #N/A | T31: =IF($D31="Enterprise Plan",$I31,NA()) -> #N/A | U31: =IF($D31="Pro Plan",$H31,NA()) -> #N/A | V31: =IF($D31="Pro Plan",$I31,NA()) -> #N/A | W31: =IF($D31="Starter Plan",$H31,NA()) -> 50 | X31: =IF($D31="Starter Plan",$I31,NA()) -> 72.26
A32: =TRIM(CLEAN(PROPER(peakflow_q1_2025_dirty!A30))) -> D-1141 | B32: =DATEVALUE(TRIM(CLEAN(peakflow_q1_2025_dirty!B30))) -> 45667 | C32: =TRIM(CLEAN(PROPER(peakflow_q1_2025_dirty!C30))) -> Nova Inc | D32: =TRIM(CLEAN(PROPER(peakflow_q1_2025_dirty!D30))) -> Enterprise Plan | E32: =TRIM(CLEAN(PROPER(peakflow_q1_2025_dirty!E30))) -> Elena Rossi | F32: =TRIM(CLEAN(PROPER(peakflow_q1_2025_dirty!F30))) -> Lukas Becker | G32: =TRIM(CLEAN(UPPER(peakflow_q1_2025_dirty!G30))) -> APAC | H32: =VALUE(TRIM((CLEAN(peakflow_q1_2025_dirty!H30)))) -> 1 | I32: =VALUE(SUBSTITUTE(peakflow_q1_2025_dirty!I30,".","," )) -> 1234.13 | J32: =H32*I32 -> 1234.13 | K32: =TEXT(B32,"MMMM") -> Januar | M32: =IF($D32="Add-On: Analytics",$H32,NA()) -> #N/A | N32: =IF($D32="Add-On: Analytics",$I32,NA()) -> #N/A | O32: =IF($D32="Add-On: Support",$H32,NA()) -> #N/A | P32: =IF($D32="Add-On: Support",$I32,NA()) -> #N/A | Q32: =IF($D32="Business Plan",$H32,NA()) -> #N/A | R32: =IF($D32="Business Plan",$I32,NA()) -> #N/A | S32: =IF($D32="Enterprise Plan",$H32,NA()) -> 1 | T32: =IF($D32="Enterprise Plan",$I32,NA()) -> 1234.13 | U32: =IF($D32="Pro Plan",$H32,NA()) -> #N/A | V32: =IF($D32="Pro Plan",$I32,NA()) -> #N/A | W32: =IF($D32="Starter Plan",$H32,NA()) -> #N/A | X32: =IF($D32="Starter Plan",$I32,NA()) -> #N/A
A33: =TRIM(CLEAN(PROPER(peakflow_q1_2025_dirty!A31))) -> D-1155 | B33: =DATEVALUE(TRIM(CLEAN(peakflow_q1_2025_dirty!B31))) -> 45667 | C33: =TRIM(CLEAN(PROPER(peakflow_q1_2025_dirty!C31))) -> Juniper Group | D33: =TRIM(CLEAN(PROPER(peakflow_q1_2025_dirty!D31))) -> Pro Plan | E33: =TRIM(CLEAN(PROPER(peakflow_q1_2025_dirty!E31))) -> Nina Petrov | F33: =TRIM(CLEAN(PROPER(peakflow_q1_2025_dirty!F31))) -> Lukas Becker | G33: =TRIM(CLEAN(PROPER(peakflow_q1_2025_dirty!G31))) -> North America | H33: =VALUE(TRIM((CLEAN(peakflow_q1_2025_dirty!H31)))) -> 1 | I33: =VALUE(SUBSTITUTE(peakflow_q1_2025_dirty!I31,".","," )) -> 219.47 | J33: =H33*I33 -> 219.47 | K33: =TEXT(B33,"MMMM") -> Januar | M33: =IF($D33="Add-On: Analytics",$H33,NA()) -> #N/A | N33: =IF($D33="Add-On: Analytics",$I33,NA()) -> #N/A | O33: =IF($D33="Add-On: Support",$H33,NA()) -> #N/A | P33: =IF($D33="Add-On: Support",$I33,NA()) -> #N/A | Q33: =IF($D33="Business Plan",$H33,NA()) -> #N/A | R33: =IF($D33="Business Plan",$I33,NA()) -> #N/A | S33: =IF($D33="Enterprise Plan",$H33,NA()) -> #N/A | T33: =IF($D33="Enterprise Plan",$I33,NA()) -> #N/A | U33: =IF($D33="Pro Plan",$H33,NA()) -> 1 | V33: =IF($D33="Pro Plan",$I33,NA()) -> 219.47 | W33: =IF($D33="Starter Plan",$H33,NA()) -> #N/A | X33: =IF($D33="Starter Plan",$I33,NA()) -> #N/A
A34: =TRIM(CLEAN(PROPER(peakflow_q1_2025_dirty!A32))) -> D-1209 | B34: =DATEVALUE(TRIM(CLEAN(peakflow_q1_2025_dirty!B32))) -> 45667 | C34: =TRIM(CLEAN(PROPER(peakflow_q1_2025_dirty!C32))) -> Lattice Co | D34: =TRIM(CLEAN(PROPER(peakflow_q1_2025_dirty!D32))) -> Pro Plan | E34: =TRIM(CLEAN(PROPER(peakflow_q1_2025_dirty!E32))) -> Elena Rossi | F34: =TRIM(CLEAN(PROPER(peakflow_q1_2025_dirty!F32))) -> Lukas Becker | G34: =TRIM(CLEAN(PROPER(peakflow_q1_2025_dirty!G32))) -> North America | H34: =VALUE(TRIM((CLEAN(peakflow_q1_2025_dirty!H32)))) -> 1 | I34: =VALUE(SUBSTITUTE(peakflow_q1_2025_dirty!I32,".","," )) -> 276.18 | J34: =H34*I34 -> 276.18 | K34: =TEXT(B34,"MMMM") -> Januar | M34: =IF($D34="Add-On: Analytics",$H34,NA()) -> #N/A | N34: =IF($D34="Add-On: Analytics",$I34,NA()) -> #N/A | O34: =IF($D34="Add-On: Support",$H34,NA()) -> #N/A | P34: =IF($D34="Add-On: Support",$I34,NA()) -> #N/A | Q34: =IF($D34="Business Plan",$H34,NA()) -> #N/A | R34: =IF($D34="Business Plan",$I34,NA()) -> #N/A | S34: =IF($D34="Enterprise Plan",$H34,NA()) -> #N/A | T34: =IF($D34="Enterprise Plan",$I34,NA()) -> #N/A | U34: =IF($D34="Pro Plan",$H34,NA()) -> 1 | V34: =IF($D34="Pro Plan",$I34,NA()) -> 276.18 | W34: =IF($D34="Starter Plan",$H34,NA()) -> #N/A | X34: =IF($D34="Starter Plan",$I34,NA()) -> #N/A
A35: =TRIM(CLEAN(PROPER(peakflow_q1_2025_dirty!A33))) -> D-1215 | B35: =DATEVALUE(TRIM(CLEAN(peakflow_q1_2025_dirty!B33))) -> 45667 | C35: =TRIM(CLEAN(PROPER(peakflow_q1_2025_dirty!C33))) -> Helix Systems | D35: =TRIM(CLEAN(PROPER(peakflow_q1_2025_dirty!D33))) -> Starter Plan | E35: =TRIM(CLEAN(PROPER(peakflow_q1_2025_dirty!E33))) -> David Kim | F35: =TRIM(CLEAN(PROPER(peakflow_q1_2025_dirty!F33))) -> Sarah Chen | G35: =TRIM(CLEAN(UPPER(peakflow_q1_2025_dirty!G33))) -> EMEA | H35: =VALUE(TRIM((CLEAN(peakflow_q1_2025_dirty!H33)))) -> 20 | I35: =VALUE(SUBSTITUTE(peakflow_q1_2025_dirty!I33,".","," )) -> 63.25 | J35: =H35*I35 -> 1265 | K35: =TEXT(B35,"MMMM") -> Januar | M35: =IF($D35="Add-On: Analytics",$H35,NA()) -> #N/A | N35: =IF($D35="Add-On: Analytics",$I35,NA()) -> #N/A | O35: =IF($D35="Add-On: Support",$H35,NA()) -> #N/A | P35: =IF($D35="Add-On: Support",$I35,NA()) -> #N/A | Q35: =IF($D35="Business Plan",$H35,NA()) -> #N/A | R35: =IF($D35="Business Plan",$I35,NA()) -> #N/A | S35: =IF($D35="Enterprise Plan",$H35,NA()) -> #N/A | T35: =IF($D35="Enterprise Plan",$I35,NA()) -> #N/A | U35: =IF($D35="Pro Plan",$H35,NA()) -> #N/A | V35: =IF($D35="Pro Plan",$I35,NA()) -> #N/A | W35: =IF($D35="Starter Plan",$H35,NA()) -> 20 | X35: =IF($D35="Starter Plan",$I35,NA()) -> 63.25
A36: =TRIM(CLEAN(PROPER(peakflow_q1_2025_dirty!A34))) -> D-1250 | B36: =DATEVALUE(TRIM(CLEAN(peakflow_q1_2025_dirty!B34))) -> 45667 | C36: =TRIM(CLEAN(PROPER(peakflow_q1_2025_dirty!C34))) -> Kestrel Co | D36: =TRIM(CLEAN(PROPER(peakflow_q1_2025_dirty!D34))) -> Starter Plan | E36: =TRIM(CLEAN(PROPER(peakflow_q1_2025_dirty!E34))) -> James Park | F36: =TRIM(CLEAN(PROPER(peakflow_q1_2025_dirty!F34))) -> Owen Walsh | G36: =TRIM(CLEAN(PROPER(peakflow_q1_2025_dirty!G34))) -> North America | H36: =VALUE(TRIM((CLEAN(peakflow_q1_2025_dirty!H34)))) -> 1 | I36: =VALUE(SUBSTITUTE(peakflow_q1_2025_dirty!I34,".","," )) -> 70.61 | J36: =H36*I36 -> 70.61 | K36: =TEXT(B36,"MMMM") -> Januar | M36: =IF($D36="Add-On: Analytics",$H36,NA()) -> #N/A | N36: =IF($D36="Add-On: Analytics",$I36,NA()) -> #N/A | O36: =IF($D36="Add-On: Support",$H36,NA()) -> #N/A | P36: =IF($D36="Add-On: Support",$I36,NA()) -> #N/A | Q36: =IF($D36="Business Plan",$H36,NA()) -> #N/A | R36: =IF($D36="Business Plan",$I36,NA()) -> #N/A | S36: =IF($D36="Enterprise Plan",$H36,NA()) -> #N/A | T36: =IF($D36="Enterprise Plan",$I36,NA()) -> #N/A | U36: =IF($D36="Pro Plan",$H36,NA()) -> #N/A | V36: =IF($D36="Pro Plan",$I36,NA()) -> #N/A | W36: =IF($D36="Starter Plan",$H36,NA()) -> 1 | X36: =IF($D36="Starter Plan",$I36,NA()) -> 70.61
A37: =TRIM(CLEAN(PROPER(peakflow_q1_2025_dirty!A35))) -> D-1066 | B37: =DATEVALUE(TRIM(CLEAN(peakflow_q1_2025_dirty!B35))) -> 45668 | C37: =TRIM(CLEAN(PROPER(peakflow_q1_2025_dirty!C35))) -> Cascade Group | D37: =TRIM(CLEAN(PROPER(peakflow_q1_2025_dirty!D35))) -> Pro Plan | E37: =TRIM(CLEAN(PROPER(peakflow_q1_2025_dirty!E35))) -> David Kim | F37: =TRIM(CLEAN(PROPER(peakflow_q1_2025_dirty!F35))) -> Sarah Chen | G37: =TRIM(CLEAN(UPPER(peakflow_q1_2025_dirty!G35))) -> EMEA | H37: =VALUE(TRIM((CLEAN(peakflow_q1_2025_dirty!H35)))) -> 2 | I37: =VALUE(SUBSTITUTE(peakflow_q1_2025_dirty!I35,".","," )) -> 171.17 | J37: =H37*I37 -> 342.34 | K37: =TEXT(B37,"MMMM") -> Januar | M37: =IF($D37="Add-On: Analytics",$H37,NA()) -> #N/A | N37: =IF($D37="Add-On: Analytics",$I37,NA()) -> #N/A | O37: =IF($D37="Add-On: Support",$H37,NA()) -> #N/A | P37: =IF($D37="Add-On: Support",$I37,NA()) -> #N/A | Q37: =IF($D37="Business Plan",$H37,NA()) -> #N/A | R37: =IF($D37="Business Plan",$I37,NA()) -> #N/A | S37: =IF($D37="Enterprise Plan",$H37,NA()) -> #N/A | T37: =IF($D37="Enterprise Plan",$I37,NA()) -> #N/A | U37: =IF($D37="Pro Plan",$H37,NA()) -> 2 | V37: =IF($D37="Pro Plan",$I37,NA()) -> 171.17 | W37: =IF($D37="Starter Plan",$H37,NA()) -> #N/A | X37: =IF($D37="Starter Plan",$I37,NA()) -> #N/A
A38: =TRIM(CLEAN(PROPER(peakflow_q1_2025_dirty!A36))) -> D-1153 | B38: =DATEVALUE(TRIM(CLEAN(peakflow_q1_2025_dirty!B36))) -> 45668 | C38: =TRIM(CLEAN(PROPER(peakflow_q1_2025_dirty!C36))) -> Beacon Labs | D38: =TRIM(CLEAN(PROPER(peakflow_q1_2025_dirty!D36))) -> Pro Plan | E38: =TRIM(CLEAN(PROPER(peakflow_q1_2025_dirty!E36))) -> Marcus Johnson | F38: =TRIM(CLEAN(PROPER(peakflow_q1_2025_dirty!F36))) -> Sarah Chen | G38: =TRIM(CLEAN(PROPER(peakflow_q1_2025_dirty!G36))) -> North America | H38: =VALUE(TRIM((CLEAN(peakflow_q1_2025_dirty!H36)))) -> 1 | I38: =VALUE(SUBSTITUTE(peakflow_q1_2025_dirty!I36,".","," )) -> 161.18 | J38: =H38*I38 -> 161.18 | K38: =TEXT(B38,"MMMM") -> Januar | M38: =IF($D38="Add-On: Analytics",$H38,NA()) -> #N/A | N38: =IF($D38="Add-On: Analytics",$I38,NA()) -> #N/A | O38: =IF($D38="Add-On: Support",$H38,NA()) -> #N/A | P38: =IF($D38="Add-On: Support",$I38,NA()) -> #N/A | Q38: =IF($D38="Business Plan",$H38,NA()) -> #N/A | R38: =IF($D38="Business Plan",$I38,NA()) -> #N/A | S38: =IF($D38="Enterprise Plan",$H38,NA()) -> #N/A | T38: =IF($D38="Enterprise Plan",$I38,NA()) -> #N/A | U38: =IF($D38="Pro Plan",$H38,NA()) -> 1 | V38: =IF($D38="Pro Plan",$I38,NA()) -> 161.18 | W38: =IF($D38="Starter Plan",$H38,NA()) -> #N/A | X38: =IF($D38="Starter Plan",$I38,NA()) -> #N/A
A39: =TRIM(CLEAN(PROPER(peakflow_q1_2025_dirty!A37))) -> D-1180 | B39: =DATEVALUE(TRIM(CLEAN(peakflow_q1_2025_dirty!B37))) -> 45668 | C39: =TRIM(CLEAN(PROPER(peakflow_q1_2025_dirty!C37))) -> Quanta Labs | D39: =TRIM(CLEAN(PROPER(peakflow_q1_2025_dirty!D37))) -> Add-On: Analytics | E39: =TRIM(CLEAN(PROPER(peakflow_q1_2025_dirty!E37))) -> Raj Sharma | F39: =TRIM(CLEAN(PROPER(peakflow_q1_2025_dirty!F37))) -> Owen Walsh | G39: =TRIM(CLEAN(UPPER(peakflow_q1_2025_dirty!G37))) -> APAC | H39: =VALUE(TRIM((CLEAN(peakflow_q1_2025_dirty!H37)))) -> 1 | I39: =VALUE(SUBSTITUTE(peakflow_q1_2025_dirty!I37,".","," )) -> 95.39 | J39: =H39*I39 -> 95.39 | K39: =TEXT(B39,"MMMM") -> Januar | M39: =IF($D39="Add-On: Analytics",$H39,NA()) -> 1 | N39: =IF($D39="Add-On: Analytics",$I39,NA()) -> 95.39 | O39: =IF($D39="Add-On: Support",$H39,NA()) -> #N/A | P39: =IF($D39="Add-On: Support",$I39,NA()) -> #N/A | Q39: =IF($D39="Business Plan",$H39,NA()) -> #N/A | R39: =IF($D39="Business Plan",$I39,NA()) -> #N/A | S39: =IF($D39="Enterprise Plan",$H39,NA()) -> #N/A | T39: =IF($D39="Enterprise Plan",$I39,NA()) -> #N/A | U39: =IF($D39="Pro Plan",$H39,NA()) -> #N/A | V39: =IF($D39="Pro Plan",$I39,NA()) -> #N/A | W39: =IF($D39="Starter Plan",$H39,NA()) -> #N/A | X39: =IF($D39="Starter Plan",$I39,NA()) -> #N/A
A40: =TRIM(CLEAN(PROPER(peakflow_q1_2025_dirty!A38))) -> D-1219 | B40: =DATEVALUE(TRIM(CLEAN(peakflow_q1_2025_dirty!B38))) -> 45668 | C40: =TRIM(CLEAN(PROPER(peakflow_q1_2025_dirty!C38))) -> Northwind Co | D40: =TRIM(CLEAN(PROPER(peakflow_q1_2025_dirty!D38))) -> Add-On: Analytics | E40: =TRIM(CLEAN(PROPER(peakflow_q1_2025_dirty!E38))) -> David Kim | F40: =TRIM(CLEAN(PROPER(peakflow_q1_2025_dirty!F38))) -> Sarah Chen | G40: =TRIM(CLEAN(UPPER(peakflow_q1_2025_dirty!G38))) -> EMEA | H40: =VALUE(TRIM((CLEAN(peakflow_q1_2025_dirty!H38)))) -> 1 | I40: =VALUE(SUBSTITUTE(peakflow_q1_2025_dirty!I38,".","," )) -> 63.23 | J40: =H40*I40 -> 63.23 | K40: =TEXT(B40,"MMMM") -> Januar | M40: =IF($D40="Add-On: Analytics",$H40,NA()) -> 1 | N40: =IF($D40="Add-On: Analytics",$I40,NA()) -> 63.23 | O40: =IF($D40="Add-On: Support",$H40,NA()) -> #N/A | P40: =IF($D40="Add-On: Support",$I40,NA()) -> #N/A | Q40: =IF($D40="Business Plan",$H40,NA()) -> #N/A | R40: =IF($D40="Business Plan",$I40,NA()) -> #N/A | S40: =IF($D40="Enterprise Plan",$H40,NA()) -> #N/A | T40: =IF($D40="Enterprise Plan",$I40,NA()) -> #N/A | U40: =IF($D40="Pro Plan",$H40,NA()) -> #N/A | V40: =IF($D40="Pro Plan",$I40,NA()) -> #N/A | W40: =IF($D40="Starter Plan",$H40,NA()) -> #N/A | X40: =IF($D40="Starter Plan",$I40,NA()) -> #N/A
...

Sheet Zusammenfassung
A1: PeakFlow Q1 2025 – Zusammenfassung
A3: Hauptkennzahlen
A4: Anzahl der Geschäfte | B4: =COUNTA('Geschäfte'!A4:A253) -> 250
A5: Gesamtumsatz | B5: =SUM('Geschäfte'!J4:J253) -> 364634.55
A6: Durchschnittlicher Deal | B6: =AVERAGE('Geschäfte'!J4:J253) -> 1458.5382
A7: Median | B7: =MEDIAN('Geschäfte'!J4:J253) -> 386.76
A8: Minimum | B8: =MIN('Geschäfte'!J4:J253) -> 41.17
A9: Maximum | B9: =MAX('Geschäfte'!J4:J253) -> 46616
A10: Spannweite | B10: =B9-B8 -> 46574.83
A11: Standardabweichung | B11: =STDEV('Geschäfte'!J4:J253) -> 4165.1839
A12: Q1 | B12: =quartile('Geschäfte'!J4:J253,1) -> 133.4775
A13: Q3 | B13: =quartile('Geschäfte'!J4:J253,3) -> 1069.4625
A14: Interquartilsabstand | B14: =B13-B12 -> 935.985
A16: Der Durchschnitt beträgt 1.458,54 $, der Median aber nur 386,76 $. Der deutlich höhere Durchschnitt zeigt, dass einige sehr große Geschäfte den Durchschnitt nach oben ziehen. Die Verteilung der Geschäftsgrößen ist deshalb rechtsschief.
A18: Umsatz nach Monat
A19: Monat | B19: Gesamtsumsatz | C19: Anzahl der Geschäfte | D19: Durchschnitt
A20: Januar | B20: =SUMIFS('Geschäfte'!$J$4:$J$253,'Geschäfte'!$K$4:$K$253,A20) -> 186600.12 | C20: {=COUNTIF('Geschäfte'!$K$4:$K$253,A20)} -> 98 | D20: =AVERAGEIF('Geschäfte'!$K$4:$K$253,A20,'Geschäfte'!$J$4:$J$253) -> 1904.0829
A21: Februar | B21: =SUMIFS('Geschäfte'!$J$4:$J$253,'Geschäfte'!$K$4:$K$253,A21) -> 85430.35 | C21: {=COUNTIF('Geschäfte'!$K$4:$K$253,A21)} -> 70 | D21: =AVERAGEIF('Geschäfte'!$K$4:$K$253,A21,'Geschäfte'!$J$4:$J$253) -> 1220.4336
A22: März | B22: =SUMIFS('Geschäfte'!$J$4:$J$253,'Geschäfte'!$K$4:$K$253,A22) -> 92604.08 | C22: {=COUNTIF('Geschäfte'!$K$4:$K$253,A22)} -> 82 | D22: =AVERAGEIF('Geschäfte'!$K$4:$K$253,A22,'Geschäfte'!$J$4:$J$253) -> 1129.318
A23: Gesamt | B23: =SUM(B20:B22) -> 364634.55 | C23: =SUM(C20:C22) -> 250 | D23: =AVERAGE('Geschäfte'!J4:J253) -> 1458.5382
A25: Umsatz nach Region
A26: Region | B26: Anzahl der Geschäfte | C26: Gesamtsumsatz | D26: Durchschnitt
A27: =IFERROR(__xludf.DUMMYFUNCTION("SORT(UNIQUE(FILTER('Geschäfte'!G4:G253,'Geschäfte'!G4:G253<>"""")))"),"APAC") -> APAC | B27: {=COUNTIF('Geschäfte'!$G$4:$G$253,A27)} -> 66 | C27: =SUMIFS('Geschäfte'!$J$4:$J$253,'Geschäfte'!$G$4:$G$253,A27) -> 120025.49 | D27: =AVERAGEIF('Geschäfte'!$G$4:$G$253,A27,'Geschäfte'!$J$4:$J$253) -> 1818.568
A28: =IFERROR(__xludf.DUMMYFUNCTION("""COMPUTED_VALUE"""),"EMEA") -> EMEA | B28: {=COUNTIF('Geschäfte'!$G$4:$G$253,A28)} -> 65 | C28: =SUMIFS('Geschäfte'!$J$4:$J$253,'Geschäfte'!$G$4:$G$253,A28) -> 78148.92 | D28: =AVERAGEIF('Geschäfte'!$G$4:$G$253,A28,'Geschäfte'!$J$4:$J$253) -> 1202.2911
A29: =IFERROR(__xludf.DUMMYFUNCTION("""COMPUTED_VALUE"""),"LATAM") -> LATAM | B29: {=COUNTIF('Geschäfte'!$G$4:$G$253,A29)} -> 53 | C29: =SUMIFS('Geschäfte'!$J$4:$J$253,'Geschäfte'!$G$4:$G$253,A29) -> 93875.14 | D29: =AVERAGEIF('Geschäfte'!$G$4:$G$253,A29,'Geschäfte'!$J$4:$J$253) -> 1771.2291
A30: =IFERROR(__xludf.DUMMYFUNCTION("""COMPUTED_VALUE"""),"North America") -> North America | B30: {=COUNTIF('Geschäfte'!$G$4:$G$253,A30)} -> 66 | C30: =SUMIFS('Geschäfte'!$J$4:$J$253,'Geschäfte'!$G$4:$G$253,A30) -> 72585 | D30: =AVERAGEIF('Geschäfte'!$G$4:$G$253,A30,'Geschäfte'!$J$4:$J$253) -> 1099.7727
A31: Gesamt | B31: =SUM(B27:B30) -> 250 | C31: =SUM(C27:C30) -> 364634.55 | D31: =AVERAGE('Geschäfte'!J4:J253) -> 1458.5382
A33: Umsatz nach Kategorie
A34: Kategorie | B34: Anzahl der Geschäfte | C34: Gesamtsumsatz | D34: Durchschnitt | E34: % Revenue
A35: =IFERROR(__xludf.DUMMYFUNCTION("SORT(UNIQUE(FILTER('Geschäfte'!D4:D253,'Geschäfte'!D4:D253<>"""")))"),"Add-On: Analytics") -> Add-On: Analytics | B35: {=COUNTIF('Geschäfte'!$D$4:$D$253,A35)} -> 22 | C35: =SUMIFS('Geschäfte'!$J$4:$J$253,'Geschäfte'!$D$4:$D$253,A35) -> 11705.37 | D35: =AVERAGEIF('Geschäfte'!$D$4:$D$253,A35,'Geschäfte'!$J$4:$J$253) -> 532.06227 | E35: =C35/$C$41 -> 0.032101648
A36: =IFERROR(__xludf.DUMMYFUNCTION("""COMPUTED_VALUE"""),"Add-On: Support") -> Add-On: Support | B36: {=COUNTIF('Geschäfte'!$D$4:$D$253,A36)} -> 18 | C36: =SUMIFS('Geschäfte'!$J$4:$J$253,'Geschäfte'!$D$4:$D$253,A36) -> 8208.19 | D36: =AVERAGEIF('Geschäfte'!$D$4:$D$253,A36,'Geschäfte'!$J$4:$J$253) -> 456.01056 | E36: =C36/$C$41 -> 0.02251073
A37: =IFERROR(__xludf.DUMMYFUNCTION("""COMPUTED_VALUE"""),"Business Plan") -> Business Plan | B37: {=COUNTIF('Geschäfte'!$D$4:$D$253,A37)} -> 43 | C37: =SUMIFS('Geschäfte'!$J$4:$J$253,'Geschäfte'!$D$4:$D$253,A37) -> 56431.16 | D37: =AVERAGEIF('Geschäfte'!$D$4:$D$253,A37,'Geschäfte'!$J$4:$J$253) -> 1312.3526 | E37: =C37/$C$41 -> 0.15476087
A38: =IFERROR(__xludf.DUMMYFUNCTION("""COMPUTED_VALUE"""),"Enterprise Plan") -> Enterprise Plan | B38: {=COUNTIF('Geschäfte'!$D$4:$D$253,A38)} -> 23 | C38: =SUMIFS('Geschäfte'!$J$4:$J$253,'Geschäfte'!$D$4:$D$253,A38) -> 170914.03 | D38: =AVERAGEIF('Geschäfte'!$D$4:$D$253,A38,'Geschäfte'!$J$4:$J$253) -> 7431.0448 | E38: =C38/$C$41 -> 0.46872692
A39: =IFERROR(__xludf.DUMMYFUNCTION("""COMPUTED_VALUE"""),"Pro Plan") -> Pro Plan | B39: {=COUNTIF('Geschäfte'!$D$4:$D$253,A39)} -> 70 | C39: =SUMIFS('Geschäfte'!$J$4:$J$253,'Geschäfte'!$D$4:$D$253,A39) -> 85206.85 | D39: =AVERAGEIF('Geschäfte'!$D$4:$D$253,A39,'Geschäfte'!$J$4:$J$253) -> 1217.2407 | E39: =C39/$C$41 -> 0.23367739
A40: =IFERROR(__xludf.DUMMYFUNCTION("""COMPUTED_VALUE"""),"Starter Plan") -> Starter Plan | B40: {=COUNTIF('Geschäfte'!$D$4:$D$253,A40)} -> 74 | C40: =SUMIFS('Geschäfte'!$J$4:$J$253,'Geschäfte'!$D$4:$D$253,A40) -> 32168.95 | D40: =AVERAGEIF('Geschäfte'!$D$4:$D$253,A40,'Geschäfte'!$J$4:$J$253) -> 434.71554 | E40: =C40/$C$41 -> 0.088222441
